<sdf version="1.8">
  <model name="diff_drive">

    <!-- ═══════════════════════════════════════════════
         CHASSIS
         Size: 0.4 × 0.3 × 0.15 m   mass: 5.0 kg
         z pose = wheel_radius + chassis_half_height
                = 0.1 + 0.075 = 0.175 m
         Inertia (box): your values from the tool are correct
           Ixx = 5/12*(0.3²+0.15²) = 0.046875
           Iyy = 5/12*(0.4²+0.15²) = 0.076041
           Izz = 5/12*(0.4²+0.3²)  = 0.104166
         ═══════════════════════════════════════════════ -->
    <link name="chassis">
      <pose>0 0 0.175 0 0 0</pose> 
      <inertial>
        <mass>5.0</mass>
        <inertia>
          <ixx>0.046875</ixx><ixy>0</ixy><ixz>0</ixz>
          <iyy>0.076041</iyy><iyz>0</iyz>
          <izz>0.104166</izz>
        </inertia>
      </inertial>
      <visual name="visual_chassis">
        <geometry><box><size>0.4 0.3 0.15</size></box></geometry>
        <material>
          <ambient>0.2 0.2 0.8 1</ambient>
          <diffuse>0.2 0.2 0.8 1</diffuse>
          <specular>0.3 0.3 0.3 1</specular>
        </material>
      </visual>
      <collision name="collision_chassis">
        <geometry><box><size>0.4 0.3 0.15</size></box></geometry>
        <surface>
          <friction><ode><mu>0.6</mu><mu2>0.6</mu2></ode></friction>
          <contact><ode><min_depth>0.001</min_depth></ode></contact>
        </surface>
      </collision>
    </link>

    <!-- ═══════════════════════════════════════════════
         WHEELS  (4 ×)
         r=0.1m  l=0.05m  mass=0.5kg
         Inertia (cylinder, FIXED from 0.00135):
           Ixx=Iyy = 0.5/12*(3×0.01+0.0025) = 0.00219
           Izz     = 0.5/2 × 0.01           = 0.00250

         Pose relative to chassis:
           x = ±0.15  (half wheelbase)
           y = ±(chassis_half_W + wheel_half_L)
             = ±(0.15 + 0.025) = ±0.175
           z = -(chassis_half_H) = -0.075
           rotation = -1.5708 around x (lay cylinder on side)
         ═══════════════════════════════════════════════ -->

    <!-- FRONT LEFT -->
    <link name="front_left_wheel">
      <pose relative_to="chassis">0.15 0.175 -0.075 -1.5708 0 0</pose>
      <inertial>
        <mass>0.5</mass>
        <inertia>
          <ixx>0.00219</ixx><ixy>0</ixy><ixz>0</ixz>
          <iyy>0.00219</iyy><iyz>0</iyz>
          <izz>0.00250</izz>
        </inertia>
      </inertial>
      <visual name="visual">
        <geometry><cylinder><radius>0.1</radius><length>0.05</length></cylinder></geometry>
        <material>
          <ambient>0.1 0.1 0.1 1</ambient>
          <diffuse>0.1 0.1 0.1 1</diffuse>
        </material>
      </visual>
      <collision name="collision">
        <geometry><cylinder><radius>0.1</radius><length>0.05</length></cylinder></geometry>
        <surface>
          <friction><ode><mu>1.0</mu><mu2>0.7</mu2></ode></friction>
          <contact><ode><min_depth>0.001</min_depth><kp>1e6</kp><kd>100</kd></ode></contact>
        </surface>
      </collision>
    </link>

    <joint name="front_left_wheel_joint" type="revolute">
      <pose relative_to="front_left_wheel"/>
      <parent>chassis</parent>
      <child>front_left_wheel</child>
      <axis>
        <xyz expressed_in="__model__">0 1 0</xyz>  <!-- FIXED: was 0 0 1 -->
        <limit>
          <lower>-1.79769e+308</lower>
          <upper>1.79769e+308</upper>
          <effort>15.0</effort>
          <velocity>10.0</velocity>
        </limit>
        <dynamics>
          <damping>0.1</damping>   <!-- FIXED: was 0.5 — too high -->
          <friction>0.02</friction> <!-- FIXED: was 0.7 — too high -->
        </dynamics>
      </axis>
    </joint>

    <!-- FRONT RIGHT -->
    <link name="front_right_wheel">
      <pose relative_to="chassis">0.15 -0.175 -0.075 -1.5708 0 0</pose>
      <inertial>
        <mass>0.5</mass>
        <inertia>
          <ixx>0.00219</ixx><ixy>0</ixy><ixz>0</ixz>
          <iyy>0.00219</iyy><iyz>0</iyz>
          <izz>0.00250</izz>
        </inertia>
      </inertial>
      <visual name="visual">
        <geometry><cylinder><radius>0.1</radius><length>0.05</length></cylinder></geometry>
        <material>
          <ambient>0.1 0.1 0.1 1</ambient>
          <diffuse>0.1 0.1 0.1 1</diffuse>
        </material>
      </visual>
      <collision name="collision">
        <geometry><cylinder><radius>0.1</radius><length>0.05</length></cylinder></geometry>
        <surface>
          <friction><ode><mu>1.0</mu><mu2>0.7</mu2></ode></friction>
          <contact><ode><min_depth>0.001</min_depth><kp>1e6</kp><kd>100</kd></ode></contact>
        </surface>
      </collision>
    </link>

    <joint name="front_right_wheel_joint" type="revolute">
      <pose relative_to="front_right_wheel"/>
      <parent>chassis</parent>
      <child>front_right_wheel</child>
      <axis>
        <xyz expressed_in="__model__">0 1 0</xyz>
        <limit>
          <lower>-1.79769e+308</lower>
          <upper>1.79769e+308</upper>
          <effort>15.0</effort>
          <velocity>10.0</velocity>
        </limit>
        <dynamics>
          <damping>0.1</damping>
          <friction>0.02</friction>
        </dynamics>
      </axis>
    </joint>

    <!-- REAR LEFT -->
    <link name="rear_left_wheel">
      <pose relative_to="chassis">-0.15 0.175 -0.075 -1.5708 0 0</pose>
      <inertial>
        <mass>0.5</mass>
        <inertia>
          <ixx>0.00219</ixx><ixy>0</ixy><ixz>0</ixz>
          <iyy>0.00219</iyy><iyz>0</iyz>
          <izz>0.00250</izz>
        </inertia>
      </inertial>
      <visual name="visual">
        <geometry><cylinder><radius>0.1</radius><length>0.05</length></cylinder></geometry>
        <material>
          <ambient>0.1 0.1 0.1 1</ambient>
          <diffuse>0.1 0.1 0.1 1</diffuse>
        </material>
      </visual>
      <collision name="collision">
        <geometry><cylinder><radius>0.1</radius><length>0.05</length></cylinder></geometry>
        <surface>
          <friction><ode><mu>1.0</mu><mu2>0.7</mu2></ode></friction>
          <contact><ode><min_depth>0.001</min_depth><kp>1e6</kp><kd>100</kd></ode></contact>
        </surface>
      </collision>
    </link>

    <joint name="rear_left_wheel_joint" type="revolute">
      <pose relative_to="rear_left_wheel"/>
      <parent>chassis</parent>
      <child>rear_left_wheel</child>
      <axis>
        <xyz expressed_in="__model__">0 1 0</xyz>
        <limit>
          <lower>-1.79769e+308</lower>
          <upper>1.79769e+308</upper>
          <effort>15.0</effort>
          <velocity>10.0</velocity>
        </limit>
        <dynamics>
          <damping>0.1</damping>
          <friction>0.02</friction>
        </dynamics>
      </axis>
    </joint>

    <!-- REAR RIGHT -->
    <link name="rear_right_wheel">
      <pose relative_to="chassis">-0.15 -0.175 -0.075 -1.5708 0 0</pose>
      <inertial>
        <mass>0.5</mass>
        <inertia>
          <ixx>0.00219</ixx><ixy>0</ixy><ixz>0</ixz>
          <iyy>0.00219</iyy><iyz>0</iyz>
          <izz>0.00250</izz>
        </inertia>
      </inertial>
      <visual name="visual">
        <geometry><cylinder><radius>0.1</radius><length>0.05</length></cylinder></geometry>
        <material>
          <ambient>0.1 0.1 0.1 1</ambient>
          <diffuse>0.1 0.1 0.1 1</diffuse>
        </material>
      </visual>
      <collision name="collision">
        <geometry><cylinder><radius>0.1</radius><length>0.05</length></cylinder></geometry>
        <surface>
          <friction><ode><mu>1.0</mu><mu2>0.7</mu2></ode></friction>
          <contact><ode><min_depth>0.001</min_depth><kp>1e6</kp><kd>100</kd></ode></contact>
        </surface>
      </collision>
    </link>

    <joint name="rear_right_wheel_joint" type="revolute">
      <pose relative_to="rear_right_wheel"/>
      <parent>chassis</parent>
      <child>rear_right_wheel</child>
      <axis>
        <xyz expressed_in="__model__">0 1 0</xyz>
        <limit>
          <lower>-1.79769e+308</lower>
          <upper>1.79769e+308</upper>
          <effort>15.0</effort>
          <velocity>10.0</velocity>
        </limit>
        <dynamics>
          <damping>0.1</damping>
          <friction>0.02</friction>
        </dynamics>
      </axis>
    </joint>

    <!-- ═══════════════════════════════════════════════
         PLUGIN
         DiffDrive supports 4-wheel skid steer natively.
         SkidSteerDrive does not exist in Harmonic — removed.
         wheel_separation = 2 × 0.175 = 0.350 m
         ═══════════════════════════════════════════════ -->
    <plugin
      filename="gz-sim-diff-drive-system"
      name="gz::sim::systems::DiffDrive">
      <left_joint>front_left_wheel_joint</left_joint>
      <left_joint>rear_left_wheel_joint</left_joint>
      <right_joint>front_right_wheel_joint</right_joint>
      <right_joint>rear_right_wheel_joint</right_joint>
      <wheel_separation>0.35</wheel_separation>  <!-- FIXED: was 0.4 -->
      <wheel_radius>0.1</wheel_radius>
      <odom_publish_frequency>50</odom_publish_frequency>
      <max_linear_velocity>0.5</max_linear_velocity>
      <min_linear_velocity>-0.5</min_linear_velocity>
      <max_angular_velocity>1.0</max_angular_velocity>
      <min_angular_velocity>-1.0</min_angular_velocity>
      <max_linear_acceleration>1.0</max_linear_acceleration>
      <min_linear_acceleration>-1.0</min_linear_acceleration>
      <max_angular_acceleration>2.0</max_angular_acceleration>
      <min_angular_acceleration>-2.0</min_angular_acceleration>
      <topic>/model/diff_drive/cmd_vel</topic>
      <odom_topic>odom</odom_topic>
      <frame_id>odom</frame_id>
      <child_frame_id>base_link</child_frame_id>
    </plugin>

    <!-- Joint state publisher (needed for ROS tf tree) -->
    <plugin
      filename="gz-sim-joint-state-publisher-system"
      name="gz::sim::systems::JointStatePublisher">
      <topic>joint_states</topic>
    </plugin>

  </model>
</sdf>